<?xml version="1.0"?>
<robot name="uav">
<material name="gray">
  <color rgba="0.5 0.5 0.5 1"/>
</material>
<material name="black">
  <color rgba="0.1 0.1 0.1 1"/>
</material>
  <link name="uav/base_link">
    <visual>
      <material name="gray"/>
      <origin rpy="0.0 0 0" xyz="0 0 0"/>
      <geometry>
    <mesh filename="package://uav_sim_ros/rviz/Meshes/UAV/Frame.stl" scale="0.01 0.01 0.01"/>
      </geometry>
    </visual>
    <inertial>
       <origin rpy="0 0 0" xyz="0.0 0.0 0.0"/>
       <mass value="0.001" />
       <inertia ixx="0.001" ixy="0" ixz="0" iyy="0.001" iyz="0" izz="0.001" />
    </inertial>
  </link>
 <joint name="m1_joint" type="continuous">
    <axis xyz="0 0 1"/>
    <parent link="uav/base_link" />
    <child link="m1_link" />
    <origin xyz="0.20 0.20 0" rpy="0 0 0" />
  </joint>
  <link name="m1_link" >
    <inertial>
      <origin xyz="0 0 0" />
      <mass value="1.0" />
      <inertia  ixx="0.001" ixy="0.0"  ixz="0.0"  iyy="0.001"  iyz="0.0"  izz="0.001" />
    </inertial>
    <visual>
      <material name="black"/>
      <origin xyz="0 0 0"/>
      <geometry>
        <mesh filename="package://uav_sim_ros/rviz/Meshes/UAV/MotorCW.stl" scale="0.01 0.01 0.01"/>
      </geometry>
    </visual>
  </link>
 <joint name="m2_joint" type="continuous">
    <axis xyz="0 0 1"/>
    <parent link="uav/base_link" />
    <child link="m2_link" />
    <origin xyz="-0.20 -0.20 0" rpy="0 0 0" />
  </joint>
  <link name="m2_link" >
    <inertial>
      <origin xyz="0 0 0" />
      <mass value="1.0" />
      <inertia  ixx="0.001" ixy="0.0"  ixz="0.0"  iyy="0.001"  iyz="0.0"  izz="0.001" />
    </inertial>
    <visual>
      <material name="black"/>
      <origin xyz="0 0 0"/>
      <geometry>
        <mesh filename="package://uav_sim_ros/rviz/Meshes/UAV/MotorCW.stl" scale="0.01 0.01 0.01"/>
      </geometry>
    </visual>
  </link>
 <joint name="m3_joint" type="continuous">
    <axis xyz="0 0 1"/>
    <parent link="uav/base_link" />
    <child link="m3_link" />
    <origin xyz="0.20 -0.20 0" rpy="0 0 0" />
  </joint>
  <link name="m3_link" >
    <inertial>
      <origin xyz="0 0 0" />
      <mass value="1.0" />
      <inertia  ixx="0.001" ixy="0.0"  ixz="0.0"  iyy="0.001"  iyz="0.0"  izz="0.001" />
    </inertial>
    <visual>
      <material name="black"/>
      <origin xyz="0 0 0"/>
      <geometry>
        <mesh filename="package://uav_sim_ros/rviz/Meshes/UAV/MotorCCW.stl" scale="0.01 0.01 0.01"/>
      </geometry>
    </visual>
  </link>
 <joint name="m4_joint" type="continuous">
    <axis xyz="0 0 1"/>
    <parent link="uav/base_link" />
    <child link="m4_link" />
    <origin xyz="-0.20 0.20 0" rpy="0 0 0" />
  </joint>
  <link name="m4_link" >
    <inertial>
      <origin xyz="0 0 0" />
      <mass value="1.0" />
      <inertia  ixx="0.001" ixy="0.0"  ixz="0.0"  iyy="0.001"  iyz="0.0"  izz="0.001" />
    </inertial>
    <visual>
      <material name="black"/>
      <origin xyz="0 0 0"/>
      <geometry>
        <mesh filename="package://uav_sim_ros/rviz/Meshes/UAV/MotorCCW.stl" scale="0.01 0.01 0.01"/>
      </geometry>
    </visual>
  </link>
</robot>
